Workbook

Sheet 泡泡国际IP一级分类统计-金额维度
A1: 销售业绩金额 | C1: POP国际 | H1: 亚太区域 | M1: 日本 | R1: 韩国 | W1: 印尼 | AB1: 新加坡 | AG1: 泰国 | AL1: 越南 | AQ1: 马来西亚 | AV1: 新西兰 | BA1: 澳大利亚 | BF1: 欧洲区域 | BK1: 意大利 | BP1: 法国 | BU1: 英国 | BZ1: 荷兰 | CE1: 西班牙
A2: IP | B2: 商业一级 | C2: 2025-01 | D2: 2025-02 | E2: 2025-03 | F2: 2025-04 | G2: 汇总 | H2: 2025-01 | I2: 2025-02 | J2: 2025-03 | K2: 2025-04 | L2: 汇总 | M2: 2025-01 | N2: 2025-02 | O2: 2025-03 | P2: 2025-04 | Q2: 汇总 | R2: 2025-01 | S2: 2025-02 | T2: 2025-03 | U2: 2025-04 | V2: 汇总 | W2: 2025-01 | X2: 2025-02 | Y2: 2025-03 | Z2: 2025-04 | AA2: 汇总 | AB2: 2025-01 | AC2: 2025-02 | AD2: 2025-03 | AE2: 2025-04 | AF2: 汇总 | AG2: 2025-01 | AH2: 2025-02 | AI2: 2025-03 | AJ2: 2025-04 | AK2: 汇总 | AL2: 2025-01 | AM2: 2025-02 | AN2: 2025-03 | AO2: 2025-04 | AP2: 汇总 | AQ2: 2025-01 | AR2: 2025-02 | AS2: 2025-03 | AT2: 2025-04 | AU2: 汇总 | AV2: 2025-01 | AW2: 2025-02 | AX2: 2025-03 | AY2: 2025-04 | AZ2: 汇总 | BA2: 2025-01 | BB2: 2025-02 | BC2: 2025-03 | BD2: 2025-04 | BE2: 汇总 | BF2: 2025-01 | BG2: 2025-02 | BH2: 2025-03 | BI2: 2025-04 | BJ2: 汇总 | BK2: 2025-01 | BL2: 2025-02 | BM2: 2025-03 | BN2: 2025-04 | BO2: 汇总 | BP2: 2025-01 | BQ2: 2025-02 | BR2: 2025-03 | BS2: 2025-04 | BT2: 汇总 | BU2: 2025-01 | BV2: 2025-02 | BW2: 2025-03 | BX2: 2025-04 | BY2: 汇总 | BZ2: 2025-01 | CA2: 2025-02 | CB2: 2025-03 | CC2: 2025-04 | CD2: 汇总 | CE2: 2025-01 | CF2: 2025-02 | CG2: 2025-03 | CH2: 2025-04 | CI2: 汇总
A3: LABUBU | B3: 潮流玩具 | C3: =H3+BF3 -> 9478303 | D3: =I3+BG3 -> 9306257 | E3: =J3+BH3 -> 18194811 | F3: =K3+BI3 -> 14516537 | G3: =L3+BJ3 -> 51495908 | H3: =M3+R3+W3+AB3+AG3+AL3+AQ3+AV3+BA3 -> 8491534 | I3: =N3+S3+X3+AC3+AH3+AM3+AR3+AW3+BB3 -> 8335758 | J3: =O3+T3+Y3+AD3+AI3+AN3+AS3+AX3+BC3 -> 16678229 | K3: =P3+U3+Z3+AE3+AJ3+AO3+AT3+AY3+BD3 -> 12936351 | L3: =Q3+V3+AA3+AF3+AK3+AP3+AU3+AZ3+BE3 -> 46441872 | M3: 1797817 | N3: 1761726 | O3: 1898495 | P3: 1940600 | Q3: 7398638 | R3: 899980 | S3: 727987 | T3: 2060878 | U3: 1727693 | V3: 5416538 | W3: 597249 | X3: 311139 | Y3: 1011851 | Z3: 919971 | AA3: 2840210 | AB3: 93500 | AC3: 608464 | AD3: 1535825 | AE3: 1980556 | AF3: 4218345 | AG3: 2455646 | AH3: 2563438 | AI3: 7326830 | AJ3: 3465125 | AK3: 15811039 | AL3: 199380 | AM3: 253983 | AN3: 239760 | AO3: 284458 | AP3: 977581 | AQ3: 1067830 | AR3: 935926 | AS3: 1437306 | AT3: 1199817 | AU3: 4640879 | AV3: 142573 | AW3: 125094 | AX3: 141896 | AY3: 124035 | AZ3: 533598 | BA3: 1237559 | BB3: 1048001 | BC3: 1025388 | BD3: 1294096 | BE3: 4605044 | BF3: =BK3+BP3+BU3+BZ3+CE3 -> 986769 | BG3: =BL3+BQ3+BV3+CA3+CF3 -> 970499 | BH3: =BM3+BR3+BW3+CB3+CG3 -> 1516582 | BI3: =BN3+BS3+BX3+CC3+CH3 -> 1580186 | BJ3: =BO3+BT3+BY3+CD3+CI3 -> 5054036 | BK3: 47967 | BL3: 49326 | BM3: 84565 | BN3: 70610 | BO3: 252468 | BP3: 562537 | BQ3: 499432 | BR3: 729499 | BS3: 669547 | BT3: 2461015 | BU3: 281719 | BV3: 350351 | BW3: 463981 | BX3: 664926 | BY3: 1760977 | BZ3: 60455 | CA3: 49698 | CB3: 181387 | CC3: 102232 | CD3: 393772 | CE3: 34091 | CF3: 21692 | CG3: 57150 | CH3: 72871 | CI3: 185804
B4: 潮流周边 | C4: =H4+BF4 -> 4794329 | D4: =I4+BG4 -> 4351959 | E4: =J4+BH4 -> 3959718 | F4: =K4+BI4 -> 3706022 | G4: =L4+BJ4 -> 16812028 | H4: =M4+R4+W4+AB4+AG4+AL4+AQ4+AV4+BA4 -> 4129619 | I4: =N4+S4+X4+AC4+AH4+AM4+AR4+AW4+BB4 -> 3885219 | J4: =O4+T4+Y4+AD4+AI4+AN4+AS4+AX4+BC4 -> 3366022 | K4: =P4+U4+Z4+AE4+AJ4+AO4+AT4+AY4+BD4 -> 2936465 | L4: =Q4+V4+AA4+AF4+AK4+AP4+AU4+AZ4+BE4 -> 14317325 | M4: 70739 | N4: 215877 | O4: 233057 | P4: 206888 | Q4: 726561 | R4: 77340 | S4: 137066 | T4: 90651 | U4: 153588 | V4: 458645 | W4: 722035 | X4: 255143 | Y4: 429135 | Z4: 155324 | AA4: 1561637 | AB4: 13981 | AC4: 276192 | AD4: 239716 | AE4: 83146 | AF4: 613035 | AG4: 2886639 | AH4: 2687781 | AI4: 1757918 | AJ4: 1978360 | AK4: 9310698 | AL4: 72829 | AM4: 59637 | AN4: 89950 | AO4: 41020 | AP4: 263436 | AQ4: 97306 | AR4: 138478 | AS4: 132616 | AT4: 111514 | AU4: 479914 | AV4: 15221 | AW4: 10648 | AX4: 46905 | AY4: 20098 | AZ4: 92872 | BA4: 173529 | BB4: 104397 | BC4: 346074 | BD4: 186527 | BE4: 810527 | BF4: =BK4+BP4+BU4+BZ4+CE4 -> 664710 | BG4: =BL4+BQ4+BV4+CA4+CF4 -> 466740 | BH4: =BM4+BR4+BW4+CB4+CG4 -> 593696 | BI4: =BN4+BS4+BX4+CC4+CH4 -> 769557 | BJ4: =BO4+BT4+BY4+CD4+CI4 -> 2494703 | BK4: 15550 | BL4: 19718 | BM4: 9053 | BN4: 10861 | BO4: 55182 | BP4: 473249 | BQ4: 324062 | BR4: 435697 | BS4: 580419 | BT4: 1813427 | BU4: 145878 | BV4: 89940 | BW4: 122879 | BX4: 163539 | BY4: 522236 | BZ4: 18181 | CA4: 14344 | CB4: 9531 | CC4: 11346 | CD4: 53402 | CE4: 11852 | CF4: 18676 | CG4: 16536 | CH4: 3392 | CI4: 50456
B5: 毛绒玩具 | C5: =H5+BF5 -> 65588169 | D5: =I5+BG5 -> 75958711 | E5: =J5+BH5 -> 86707200 | F5: =K5+BI5 -> 125625471 | G5: =L5+BJ5 -> 353879551 | H5: =M5+R5+W5+AB5+AG5+AL5+AQ5+AV5+BA5 -> 57242034 | I5: =N5+S5+X5+AC5+AH5+AM5+AR5+AW5+BB5 -> 66437798 | J5: =O5+T5+Y5+AD5+AI5+AN5+AS5+AX5+BC5 -> 71481038 | K5: =P5+U5+Z5+AE5+AJ5+AO5+AT5+AY5+BD5 -> 100297506 | L5: =Q5+V5+AA5+AF5+AK5+AP5+AU5+AZ5+BE5 -> 295458376 | M5: 8807748 | N5: 11931036 | O5: 12591448 | P5: 14940410 | Q5: 48270642 | R5: 7358076 | S5: 11633993 | T5: 12733767 | U5: 21752440 | V5: 53478276 | W5: 10030322 | X5: 8885306 | Y5: 9116203 | Z5: 9254383 | AA5: 37286214 | AB5: 480920 | AC5: 1303902 | AD5: 1986698 | AE5: 4052115 | AF5: 7823635 | AG5: 13862893 | AH5: 17027415 | AI5: 14002116 | AJ5: 28271758 | AK5: 73164182 | AL5: 3139019 | AM5: 2973564 | AN5: 5259535 | AO5: 4845129 | AP5: 16217247 | AQ5: 8703811 | AR5: 6762917 | AS5: 7086366 | AT5: 8594316 | AU5: 31147410 | AV5: 396571 | AW5: 763215 | AX5: 931503 | AY5: 1096976 | AZ5: 3188265 | BA5: 4462674 | BB5: 5156450 | BC5: 7773402 | BD5: 7489979 | BE5: 24882505 | BF5: =BK5+BP5+BU5+BZ5+CE5 -> 8346135 | BG5: =BL5+BQ5+BV5+CA5+CF5 -> 9520913 | BH5: =BM5+BR5+BW5+CB5+CG5 -> 15226162 | BI5: =BN5+BS5+BX5+CC5+CH5 -> 25327965 | BJ5: =BO5+BT5+BY5+CD5+CI5 -> 58421175 | BK5: 1230775 | BL5: 1560434 | BM5: 1677632 | BN5: 2374817 | BO5: 6843658 | BP5: 2362284 | BQ5: 1950459 | BR5: 3208479 | BS5: 6090525 | BT5: 13611747 | BU5: 2934187 | BV5: 4109336 | BW5: 7766206 | BX5: 13147872 | BY5: 27957601 | BZ5: 980638 | CA5: 1061057 | CB5: 1654684 | CC5: 2412042 | CD5: 6108421 | CE5: 838251 | CF5: 839627 | CG5: 919161 | CH5: 1302709 | CI5: 3899748
B6: 收藏玩具 | C6: =H6+BF6 -> 533818 | D6: =I6+BG6 -> 196456 | E6: =J6+BH6 -> 222058 | F6: =K6+BI6 -> 1673630 | G6: =L6+BJ6 -> 2625962 | H6: =M6+R6+W6+AB6+AG6+AL6+AQ6+AV6+BA6 -> 487739 | I6: =N6+S6+X6+AC6+AH6+AM6+AR6+AW6+BB6 -> 140292 | J6: =O6+T6+Y6+AD6+AI6+AN6+AS6+AX6+BC6 -> 124515 | K6: =P6+U6+Z6+AE6+AJ6+AO6+AT6+AY6+BD6 -> 1620560 | L6: =Q6+V6+AA6+AF6+AK6+AP6+AU6+AZ6+BE6 -> 2373106 | M6: 207344 | N6: 44166 | O6: 6495 | Q6: 258005 | R6: 24681 | S6: 11691 | T6: 20784 | U6: 222365 | V6: 279521 | W6: 50165 | X6: 22083 | Y6: 19485 | Z6: 35876 | AA6: 127609 | AG6: 96126 | AH6: 35073 | AI6: 10392 | AJ6: 1228900 | AK6: 1370491 | AL6: 33278 | AM6: 25980 | AN6: 24681 | AO6: 33278 | AP6: 117217 | AT6: 100141 | AU6: 100141 | AV6: 16391 | AX6: 17997 | AZ6: 34388 | BA6: 59754 | BB6: 1299 | BC6: 24681 | BE6: 85734 | BF6: =BK6+BP6+BU6+BZ6+CE6 -> 46079 | BG6: =BL6+BQ6+BV6+CA6+CF6 -> 56164 | BH6: =BM6+BR6+BW6+CB6+CG6 -> 97543 | BI6: =BN6+BS6+BX6+CC6+CH6 -> 53070 | BJ6: =BO6+BT6+BY6+CD6+CI6 -> 252856 | BK6: 12494 | BL6: 22886 | BM6: 17690 | BN6: 16391 | BO6: 69461 | BP6: 9093 | BQ6: 23382 | BR6: 31979 | BS6: 17690 | BT6: 82144 | BU6: 19296 | BV6: 9896 | BW6: 42678 | BX6: 11195 | BY6: 83065 | BZ6: 5196 | CB6: 5196 | CC6: 7794 | CD6: 18186
A7: LABUBU 汇总 | C7: =H7+BF7 -> 80394619 | D7: =I7+BG7 -> 89813383 | E7: =J7+BH7 -> 109083787 | F7: =K7+BI7 -> 145521660 | G7: =L7+BJ7 -> 424813449 | H7: =M7+R7+W7+AB7+AG7+AL7+AQ7+AV7+BA7 -> 70350926 | I7: =N7+S7+X7+AC7+AH7+AM7+AR7+AW7+BB7 -> 78799067 | J7: =O7+T7+Y7+AD7+AI7+AN7+AS7+AX7+BC7 -> 91649804 | K7: =P7+U7+Z7+AE7+AJ7+AO7+AT7+AY7+BD7 -> 117790882 | L7: =Q7+V7+AA7+AF7+AK7+AP7+AU7+AZ7+BE7 -> 358590679 | M7: 10883648 | N7: 13952805 | O7: 14729495 | P7: 17087898 | Q7: 56653846 | R7: 8360077 | S7: 12510737 | T7: 14906080 | U7: 23856086 | V7: 59632980 | W7: 11399771 | X7: 9473671 | Y7: 10576674 | Z7: 10365554 | AA7: 41815670 | AB7: 588401 | AC7: 2188558 | AD7: 3762239 | AE7: 6115817 | AF7: 12655015 | AG7: 19301304 | AH7: 22313707 | AI7: 23097256 | AJ7: 34944143 | AK7: 99656410 | AL7: 3444506 | AM7: 3313164 | AN7: 5613926 | AO7: 5203885 | AP7: 17575481 | AQ7: 9868947 | AR7: 7837321 | AS7: 8656288 | AT7: 10005788 | AU7: 36368344 | AV7: 570756 | AW7: 898957 | AX7: 1138301 | AY7: 1241109 | AZ7: 3849123 | BA7: 5933516 | BB7: 6310147 | BC7: 9169545 | BD7: 8970602 | BE7: 30383810 | BF7: =BK7+BP7+BU7+BZ7+CE7 -> 10043693 | BG7: =BL7+BQ7+BV7+CA7+CF7 -> 11014316 | BH7: =BM7+BR7+BW7+CB7+CG7 -> 17433983 | BI7: =BN7+BS7+BX7+CC7+CH7 -> 27730778 | BJ7: =BO7+BT7+BY7+CD7+CI7 -> 66222770 | BK7: 1306786 | BL7: 1652364 | BM7: 1788940 | BN7: 2472679 | BO7: 7220769 | BP7: 3407163 | BQ7: 2797335 | BR7: 4405654 | BS7: 7358181 | BT7: 17968333 | BU7: 3381080 | BV7: 4559523 | BW7: 8395744 | BX7: 13987532 | BY7: 30323879 | BZ7: 1064470 | CA7: 1125099 | CB7: 1850798 | CC7: 2533414 | CD7: 6573781 | CE7: 884194 | CF7: 879995 | CG7: 992847 | CH7: 1378972 | CI7: 4136008
A8: CRYBABY | B8: 潮流玩具 | C8: =H8+BF8 -> 12456868 | D8: =I8+BG8 -> 13406779 | E8: =J8+BH8 -> 12790002 | F8: =K8+BI8 -> 8740642 | G8: =L8+BJ8 -> 47394291 | H8: =M8+R8+W8+AB8+AG8+AL8+AQ8+AV8+BA8 -> 12176566 | I8: =N8+S8+X8+AC8+AH8+AM8+AR8+AW8+BB8 -> 12965277 | J8: =O8+T8+Y8+AD8+AI8+AN8+AS8+AX8+BC8 -> 12351052 | K8: =P8+U8+Z8+AE8+AJ8+AO8+AT8+AY8+BD8 -> 8121817 | L8: =Q8+V8+AA8+AF8+AK8+AP8+AU8+AZ8+BE8 -> 45614712 | M8: 1021784 | N8: 1415029 | O8: 1482794 | P8: 1052481 | Q8: 4972088 | R8: 514944 | S8: 659432 | T8: 862424 | U8: 611314 | V8: 2648114 | W8: 940300 | X8: 1032934 | Y8: 1490459 | Z8: 817395 | AA8: 4281088 | AB8: 184491 | AC8: 1192678 | AD8: 2516669 | AE8: 1497621 | AF8: 5391459 | AG8: 7323196 | AH8: 5904047 | AI8: 2661429 | AJ8: 1901782 | AK8: 17790454 | AL8: 183936 | AM8: 420953 | AN8: 661836 | AO8: 328278 | AP8: 1595003 | AQ8: 1178832 | AR8: 1117729 | AS8: 1467442 | AT8: 1072818 | AU8: 4836821 | AV8: 63167 | AW8: 88308 | AX8: 88664 | AY8: 72793 | AZ8: 312932 | BA8: 765916 | BB8: 1134167 | BC8: 1119335 | BD8: 767335 | BE8: 3786753 | BF8: =BK8+BP8+BU8+BZ8+CE8 -> 280302 | BG8: =BL8+BQ8+BV8+CA8+CF8 -> 441502 | BH8: =BM8+BR8+BW8+CB8+CG8 -> 438950 | BI8: =BN8+BS8+BX8+CC8+CH8 -> 618825 | BJ8: =BO8+BT8+BY8+CD8+CI8 -> 1779579 | BK8: 23334 | BL8: 28226 | BM8: 34277 | BN8: 29922 | BO8: 115759 | BP8: 57777 | BQ8: 139305 | BR8: 111727 | BS8: 101954 | BT8: 410763 | BU8: 149344 | BV8: 186042 | BW8: 237181 | BX8: 417081 | BY8: 989648 | BZ8: 25599 | CA8: 45980 | CB8: 46174 | CC8: 45304 | CD8: 163057 | CE8: 24248 | CF8: 41949 | CG8: 9591 | CH8: 24564 | CI8: 100352
B9: 潮流周边 | C9: =H9+BF9 -> 7448834 | D9: =I9+BG9 -> 7482109 | E9: =J9+BH9 -> 5426848 | F9: =K9+BI9 -> 3848187 | G9: =L9+BJ9 -> 24205978 | H9: =M9+R9+W9+AB9+AG9+AL9+AQ9+AV9+BA9 -> 7325346 | I9: =N9+S9+X9+AC9+AH9+AM9+AR9+AW9+BB9 -> 7300112 | J9: =O9+T9+Y9+AD9+AI9+AN9+AS9+AX9+BC9 -> 5198240 | K9: =P9+U9+Z9+AE9+AJ9+AO9+AT9+AY9+BD9 -> 3594201 | L9: =Q9+V9+AA9+AF9+AK9+AP9+AU9+AZ9+BE9 -> 23417899 | M9: 333540 | N9: 565172 | O9: 437818 | P9: 364217 | Q9: 1700747 | R9: 279667 | S9: 463304 | T9: 499103 | U9: 377200 | V9: 1619274 | W9: 1802522 | X9: 957915 | Y9: 1029172 | Z9: 508296 | AA9: 4297905 | AB9: 10983 | AC9: 580438 | AD9: 482058 | AE9: 74037 | AF9: 1147516 | AG9: 4478015 | AH9: 3745846 | AI9: 2244195 | AJ9: 1897795 | AK9: 12365851 | AL9: 102417 | AM9: 204882 | AN9: 72866 | AO9: 45689 | AP9: 425854 | AQ9: 181670 | AR9: 363989 | AS9: 232101 | AT9: 193664 | AU9: 971424 | AV9: 16568 | AW9: 53125 | AX9: 26983 | AY9: 14604 | AZ9: 111280 | BA9: 119964 | BB9: 365441 | BC9: 173944 | BD9: 118699 | BE9: 778048 | BF9: =BK9+BP9+BU9+BZ9+CE9 -> 123488 | BG9: =BL9+BQ9+BV9+CA9+CF9 -> 181997 | BH9: =BM9+BR9+BW9+CB9+CG9 -> 228608 | BI9: =BN9+BS9+BX9+CC9+CH9 -> 253986 | BJ9: =BO9+BT9+BY9+CD9+CI9 -> 788079 | BK9: 14376 | BL9: 15014 | BM9: 11422 | BN9: 7846 | BO9: 48658 | BP9: 28443 | BQ9: 87590 | BR9: 71758 | BS9: 43289 | BT9: 231080 | BU9: 66703 | BV9: 47429 | BW9: 125600 | BX9: 184631 | BY9: 424363 | BZ9: 8116 | CA9: 26768 | CB9: 18163 | CC9: 13126 | CD9: 66173 | CE9: 5850 | CF9: 5196 | CG9: 1665 | CH9: 5094 | CI9: 17805
B10: 毛绒玩具 | C10: =H10+BF10 -> 27192110 | D10: =I10+BG10 -> 24657149 | E10: =J10+BH10 -> 23042853 | F10: =K10+BI10 -> 15280514 | G10: =L10+BJ10 -> 90172626 | H10: =M10+R10+W10+AB10+AG10+AL10+AQ10+AV10+BA10 -> 26107647 | I10: =N10+S10+X10+AC10+AH10+AM10+AR10+AW10+BB10 -> 23374265 | J10: =O10+T10+Y10+AD10+AI10+AN10+AS10+AX10+BC10 -> 21089368 | K10: =P10+U10+Z10+AE10+AJ10+AO10+AT10+AY10+BD10 -> 12952555 | L10: =Q10+V10+AA10+AF10+AK10+AP10+AU10+AZ10+BE10 -> 83523835 | M10: 2066507 | N10: 2691648 | O10: 1449691 | P10: 1018281 | Q10: 7226127 | R10: 2485652 | S10: 3195312 | T10: 4116077 | U10: 2315627 | V10: 12112668 | W10: 3556762 | X10: 3750708 | Y10: 3533800 | Z10: 2525494 | AA10: 13366764 | AB10: 23140 | AC10: 487246 | AD10: 1359094 | AE10: 394985 | AF10: 2264465 | AG10: 14224650 | AH10: 7966390 | AI10: 4583950 | AJ10: 3637087 | AK10: 30412077 | AL10: 1176145 | AM10: 1517257 | AN10: 1185004 | AO10: 821906 | AP10: 4700312 | AQ10: 1625969 | AR10: 1808115 | AS10: 3354392 | AT10: 1710770 | AU10: 8499246 | AV10: 93999 | AW10: 96038 | AX10: 106146 | AY10: 96960 | AZ10: 393143 | BA10: 854823 | BB10: 1861551 | BC10: 1401214 | BD10: 431445 | BE10: 4549033 | BF10: =BK10+BP10+BU10+BZ10+CE10 -> 1084463 | BG10: =BL10+BQ10+BV10+CA10+CF10 -> 1282884 | BH10: =BM10+BR10+BW10+CB10+CG10 -> 1953485 | BI10: =BN10+BS10+BX10+CC10+CH10 -> 2327959 | BJ10: =BO10+BT10+BY10+CD10+CI10 -> 6648791 | BK10: 82917 | BL10: 158067 | BM10: 336477 | BN10: 247003 | BO10: 824464 | BP10: 197747 | BQ10: 246796 | BR10: 340144 | BS10: 269549 | BT10: 1054236 | BU10: 608867 | BV10: 623365 | BW10: 1001513 | BX10: 1505469 | BY10: 3739214 | BZ10: 105088 | CA10: 145479 | CB10: 174254 | CC10: 179610 | CD10: 604431 | CE10: 89844 | CF10: 109177 | CG10: 101097 | CH10: 126328 | CI10: 426446
B11: 收藏玩具 | C11: =H11+BF11 -> 1797301 | D11: =I11+BG11 -> 1331112 | E11: =J11+BH11 -> 791472 | F11: =K11+BI11 -> 535143 | G11: =L11+BJ11 -> 4455028 | H11: =M11+R11+W11+AB11+AG11+AL11+AQ11+AV11+BA11 -> 1783810 | I11: =N11+S11+X11+AC11+AH11+AM11+AR11+AW11+BB11 -> 1302631 | J11: =O11+T11+Y11+AD11+AI11+AN11+AS11+AX11+BC11 -> 779480 | K11: =P11+U11+Z11+AE11+AJ11+AO11+AT11+AY11+BD11 -> 505163 | L11: =Q11+V11+AA11+AF11+AK11+AP11+AU11+AZ11+BE11 -> 4371084 | M11: 133411 | N11: 79447 | O11: 88441 | P11: 73451 | Q11: 374750 | R11: 52465 | S11: 44970 | T11: 82445 | U11: 46469 | V11: 226349 | W11: 262325 | X11: 38974 | Y11: 29980 | Z11: 41972 | AA11: 373251 | AB11: 56962 | AC11: 113924 | AD11: 41972 | AE11: 2998 | AF11: 215856 | AG11: 920386 | AH11: 783977 | AI11: 214357 | AJ11: 196369 | AK11: 2115089 | AL11: 92938 | AM11: 53964 | AN11: 166389 | AO11: 29980 | AP11: 343271 | AQ11: 61459 | AR11: 145403 | AS11: 98934 | AT11: 70453 | AU11: 376249 | AV11: 14990 | AW11: 1499 | AX11: 7495 | AY11: 5996 | AZ11: 29980 | BA11: 188874 | BB11: 40473 | BC11: 49467 | BD11: 37475 | BE11: 316289 | BF11: =BK11+BP11+BU11+BZ11+CE11 -> 13491 | BG11: =BL11+BQ11+BV11+CA11+CF11 -> 28481 | BH11: =BM11+BR11+BW11+CB11+CG11 -> 11992 | BI11: =BN11+BS11+BX11+CC11+CH11 -> 29980 | BJ11: =BO11+BT11+BY11+CD11+CI11 -> 83944 | BN11: 4497 | BO11: 4497 | BQ11: 8994 | BR11: 4497 | BS11: 1499 | BT11: 14990 | BU11: 7495 | BV11: 14990 | BW11: 5996 | BX11: 22485 | BY11: 50966 | CC11: 1499 | CD11: 1499 | CE11: 5996 | CF11: 4497 | CG11: 1499 | CI11: 11992
A12: CRYBABY 汇总 | C12: =H12+BF12 -> 48895113 | D12: =I12+BG12 -> 46877149 | E12: =J12+BH12 -> 42051175 | F12: =K12+BI12 -> 28404486 | G12: =L12+BJ12 -> 166227923 | H12: =M12+R12+W12+AB12+AG12+AL12+AQ12+AV12+BA12 -> 47393369 | I12: =N12+S12+X12+AC12+AH12+AM12+AR12+AW12+BB12 -> 44942285 | J12: =O12+T12+Y12+AD12+AI12+AN12+AS12+AX12+BC12 -> 39418140 | K12: =P12+U12+Z12+AE12+AJ12+AO12+AT12+AY12+BD12 -> 25173736 | L12: =Q12+V12+AA12+AF12+AK12+AP12+AU12+AZ12+BE12 -> 156927530 | M12: 3555242 | N12: 4751296 | O12: 3458744 | P12: 2508430 | Q12: 14273712 | R12: 3332728 | S12: 4363018 | T12: 5560049 | U12: 3350610 | V12: 16606405 | W12: 6561909 | X12: 5780531 | Y12: 6083411 | Z12: 3893157 | AA12: 22319008 | AB12: 275576 | AC12: 2374286 | AD12: 4399793 | AE12: 1969641 | AF12: 9019296 | AG12: 26946247 | AH12: 18400260 | AI12: 9703931 | AJ12: 7633033 | AK12: 62683471 | AL12: 1555436 | AM12: 2197056 | AN12: 2086095 | AO12: 1225853 | AP12: 7064440 | AQ12: 3047930 | AR12: 3435236 | AS12: 5152869 | AT12: 3047705 | AU12: 14683740 | AV12: 188724 | AW12: 238970 | AX12: 229288 | AY12: 190353 | AZ12: 847335 | BA12: 1929577 | BB12: 3401632 | BC12: 2743960 | BD12: 1354954 | BE12: 9430123 | BF12: =BK12+BP12+BU12+BZ12+CE12 -> 1501744 | BG12: =BL12+BQ12+BV12+CA12+CF12 -> 1934864 | BH12: =BM12+BR12+BW12+CB12+CG12 -> 2633035 | BI12: =BN12+BS12+BX12+CC12+CH12 -> 3230750 | BJ12: =BO12+BT12+BY12+CD12+CI12 -> 9300393 | BK12: 120627 | BL12: 201307 | BM12: 382176 | BN12: 289268 | BO12: 993378 | BP12: 283967 | BQ12: 482685 | BR12: 528126 | BS12: 416291 | BT12: 1711069 | BU12: 832409 | BV12: 871826 | BW12: 1370290 | BX12: 2129666 | BY12: 5204191 | BZ12: 138803 | CA12: 218227 | CB12: 238591 | CC12: 239539 | CD12: 835160 | CE12: 125938 | CF12: 160819 | CG12: 113852 | CH12: 155986 | CI12: 556595
A13: MOLLY | B13: 潮流玩具 | C13: =H13+BF13 -> 5890275 | D13: =I13+BG13 -> 3996062 | E13: =J13+BH13 -> 2948047 | F13: =K13+BI13 -> 2583000 | G13: =L13+BJ13 -> 15417384 | H13: =M13+R13+W13+AB13+AG13+AL13+AQ13+AV13+BA13 -> 5730128 | I13: =N13+S13+X13+AC13+AH13+AM13+AR13+AW13+BB13 -> 3829552 | J13: =O13+T13+Y13+AD13+AI13+AN13+AS13+AX13+BC13 -> 2754653 | K13: =P13+U13+Z13+AE13+AJ13+AO13+AT13+AY13+BD13 -> 2398938 | L13: =Q13+V13+AA13+AF13+AK13+AP13+AU13+AZ13+BE13 -> 14713271 | M13: 465388 | N13: 671173 | O13: 322495 | P13: 273351 | Q13: 1732407 | R13: 346871 | S13: 273551 | T13: 255426 | U13: 187239 | V13: 1063087 | W13: 355701 | X13: 409882 | Y13: 272413 | Z13: 174594 | AA13: 1212590 | AB13: 282085 | AC13: 511564 | AD13: 233205 | AE13: 205895 | AF13: 1232749 | AG13: 3507869 | AH13: 1226201 | AI13: 868324 | AJ13: 949413 | AK13: 6551807 | AL13: 60465 | AM13: 87678 | AN13: 84860 | AO13: 87036 | AP13: 320039 | AQ13: 376272 | AR13: 364055 | AS13: 263090 | AT13: 194460 | AU13: 1197877 | AV13: 46907 | AW13: 24431 | AX13: 52842 | AY13: 31617 | AZ13: 155797 | BA13: 288570 | BB13: 261017 | BC13: 401998 | BD13: 295333 | BE13: 1246918 | BF13: =BK13+BP13+BU13+BZ13+CE13 -> 160147 | BG13: =BL13+BQ13+BV13+CA13+CF13 -> 166510 | BH13: =BM13+BR13+BW13+CB13+CG13 -> 193394 | BI13: =BN13+BS13+BX13+CC13+CH13 -> 184062 | BJ13: =BO13+BT13+BY13+CD13+CI13 -> 704113 | BK13: 3082 | BL13: 17066 | BM13: 10741 | BN13: 4921 | BO13: 35810 | BP13: 41419 | BQ13: 37656 | BR13: 30129 | BS13: 32717 | BT13: 141921 | BU13: 90430 | BV13: 74475 | BW13: 134997 | BX13: 117024 | BY13: 416926 | BZ13: 8273 | CA13: 9507 | CB13: 6689 | CC13: 7939 | CD13: 32408 | CE13: 16943 | CF13: 27806 | CG13: 10838 | CH13: 21461 | CI13: 77048
B14: 潮流周边 | C14: =H14+BF14 -> 1825922 | D14: =I14+BG14 -> 1630459 | E14: =J14+BH14 -> 1605663 | F14: =K14+BI14 -> 963153 | G14: =L14+BJ14 -> 6025197 | H14: =M14+R14+W14+AB14+AG14+AL14+AQ14+AV14+BA14 -> 1806750 | I14: =N14+S14+X14+AC14+AH14+AM14+AR14+AW14+BB14 -> 1606920 | J14: =O14+T14+Y14+AD14+AI14+AN14+AS14+AX14+BC14 -> 1528625 | K14: =P14+U14+Z14+AE14+AJ14+AO14+AT14+AY14+BD14 -> 870810 | L14: =Q14+V14+AA14+AF14+AK14+AP14+AU14+AZ14+BE14 -> 5813105 | M14: 106890 | N14: 132307 | O14: 87466 | P14: 61489 | Q14: 388152 | R14: 30679 | S14: 25395 | T14: 13720 | U14: 12969 | V14: 82763 | W14: 265032 | X14: 238562 | Y14: 180926 | Z14: 97592 | AA14: 782112 | AB14: 112500 | AC14: 107578 | AD14: 50035 | AE14: 15676 | AF14: 285789 | AG14: 1104420 | AH14: 815777 | AI14: 1007503 | AJ14: 601006 | AK14: 3528706 | AL14: 61757 | AM14: 105523 | AN14: 43130 | AO14: 27648 | AP14: 238058 | AQ14: 109947 | AR14: 42918 | AS14: 85990 | AT14: 29218 | AU14: 268073 | AV14: 2913 | AW14: 15494 | AX14: 7120 | AY14: 5127 | AZ14: 30654 | BA14: 12612 | BB14: 123366 | BC14: 52735 | BD14: 20085 | BE14: 208798 | BF14: =BK14+BP14+BU14+BZ14+CE14 -> 19172 | BG14: =BL14+BQ14+BV14+CA14+CF14 -> 23539 | BH14: =BM14+BR14+BW14+CB14+CG14 -> 77038 | BI14: =BN14+BS14+BX14+CC14+CH14 -> 92343 | BJ14: =BO14+BT14+BY14+CD14+CI14 -> 212092 | BK14: 188 | BL14: 395 | BM14: 913 | BN14: 5220 | BO14: 6716 | BP14: 7253 | BQ14: 6359 | BR14: 7242 | BS14: 47690 | BT14: 68544 | BU14: 8443 | BV14: 11405 | BW14: 66263 | BX14: 36672 | BY14: 122783 | BZ14: 640 | CA14: 2030 | CB14: 1478 | CC14: 1261 | CD14: 5409 | CE14: 2648 | CF14: 3350 | CG14: 1142 | CH14: 1500 | CI14: 8640
B15: 毛绒玩具 | C15: =H15+BF15 -> 2397723 | D15: =I15+BG15 -> 1435899 | E15: =J15+BH15 -> 1270650 | F15: =K15+BI15 -> 921447 | G15: =L15+BJ15 -> 6025719 | H15: =M15+R15+W15+AB15+AG15+AL15+AQ15+AV15+BA15 -> 2367924 | I15: =N15+S15+X15+AC15+AH15+AM15+AR15+AW15+BB15 -> 1281744 | J15: =O15+T15+Y15+AD15+AI15+AN15+AS15+AX15+BC15 -> 1211052 | K15: =P15+U15+Z15+AE15+AJ15+AO15+AT15+AY15+BD15 -> 849078 | L15: =Q15+V15+AA15+AF15+AK15+AP15+AU15+AZ15+BE15 -> 5709798 | M15: 341463 | N15: 210915 | O15: 197886 | P15: 196854 | Q15: 947118 | R15: 115971 | S15: 90816 | T15: 95718 | U15: 11481 | V15: 313986 | W15: 174924 | X15: 56115 | Y15: 228846 | Z15: 147705 | AA15: 607590 | AB15: 23220 | AC15: 17028 | AD15: 181890 | AE15: 151962 | AF15: 374100 | AG15: 1312188 | AH15: 431376 | AI15: 336690 | AJ15: 195951 | AK15: 2276205 | AL15: 60243 | AM15: 25284 | AN15: 28896 | AO15: 23736 | AP15: 138159 | AQ15: 201111 | AR15: 124614 | AS15: 112101 | AT15: 95202 | AU15: 533028 | AV15: 9675 | AW15: 34830 | AX15: 20382 | AY15: 16512 | AZ15: 81399 | BA15: 129129 | BB15: 290766 | BC15: 8643 | BD15: 9675 | BE15: 438213 | BF15: =BK15+BP15+BU15+BZ15+CE15 -> 29799 | BG15: =BL15+BQ15+BV15+CA15+CF15 -> 154155 | BH15: =BM15+BR15+BW15+CB15+CG15 -> 59598 | BI15: =BN15+BS15+BX15+CC15+CH15 -> 72369 | BJ15: =BO15+BT15+BY15+CD15+CI15 -> 315921 | BK15: 29799 | BL15: 18060 | BN15: 10707 | BO15: 58566 | BQ15: 49020 | BR15: 12513 | BT15: 61533 | BV15: 58695 | BW15: 29799 | BX15: 61662 | BY15: 150156 | CA15: 28380 | CB15: 17286 | CD15: 45666
B16: 收藏玩具 | C16: =H16+BF16 -> 23495521 | D16: =I16+BG16 -> 23322120 | E16: =J16+BH16 -> 21513586 | F16: =K16+BI16 -> 24963668 | G16: =L16+BJ16 -> 93294895 | H16: =M16+R16+W16+AB16+AG16+AL16+AQ16+AV16+BA16 -> 22587744 | I16: =N16+S16+X16+AC16+AH16+AM16+AR16+AW16+BB16 -> 22665089 | J16: =O16+T16+Y16+AD16+AI16+AN16+AS16+AX16+BC16 -> 20678926 | K16: =P16+U16+Z16+AE16+AJ16+AO16+AT16+AY16+BD16 -> 24227188 | L16: =Q16+V16+AA16+AF16+AK16+AP16+AU16+AZ16+BE16 -> 90158947 | M16: 3831512 | N16: 3325894 | O16: 3930917 | P16: 2019344 | Q16: 13107667 | R16: 1254804 | S16: 1653558 | T16: 1793823 | U16: 1538167 | V16: 6240352 | W16: 2777546 | X16: 2013738 | Y16: 1882473 | Z16: 2070002 | AA16: 8743759 | AB16: 700986 | AC16: 2154394 | AD16: 1093887 | AE16: 1939199 | AF16: 5888466 | AG16: 9009403 | AH16: 8941145 | AI16: 7669207 | AJ16: 13225843 | AK16: 38845598 | AL16: 593887 | AM16: 839957 | AN16: 818105 | AO16: 615755 | AP16: 2867704 | AQ16: 1251387 | AR16: 1775766 | AS16: 1490763 | AT16: 1810098 | AU16: 6328014 | AV16: 253875 | AW16: 217506 | AX16: 249537 | AY16: 117102 | AZ16: 838020 | BA16: 2914344 | BB16: 1743131 | BC16: 1750214 | BD16: 891678 | BE16: 7299367 | BF16: =BK16+BP16+BU16+BZ16+CE16 -> 907777 | BG16: =BL16+BQ16+BV16+CA16+CF16 -> 657031 | BH16: =BM16+BR16+BW16+CB16+CG16 -> 834660 | BI16: =BN16+BS16+BX16+CC16+CH16 -> 736480 | BJ16: =BO16+BT16+BY16+CD16+CI16 -> 3135948 | BK16: 53091 | BL16: 60662 | BM16: 105751 | BN16: 110109 | BO16: 329613 | BP16: 187737 | BQ16: 140350 | BR16: 107452 | BS16: 101310 | BT16: 536849 | BU16: 467704 | BV16: 286265 | BW16: 486708 | BX16: 421695 | BY16: 1662372 | BZ16: 130417 | CA16: 118553 | CB16: 120560 | CC16: 81282 | CD16: 450812 | CE16: 68828 | CF16: 51201 | CG16: 14189 | CH16: 22084 | CI16: 156302
A17: MOLLY 汇总 | C17: =H17+BF17 -> 33609441 | D17: =I17+BG17 -> 30384540 | E17: =J17+BH17 -> 27337946 | F17: =K17+BI17 -> 29431268 | G17: =L17+BJ17 -> 120763195 | H17: =M17+R17+W17+AB17+AG17+AL17+AQ17+AV17+BA17 -> 32492546 | I17: =N17+S17+X17+AC17+AH17+AM17+AR17+AW17+BB17 -> 29383305 | J17: =O17+T17+Y17+AD17+AI17+AN17+AS17+AX17+BC17 -> 26173256 | K17: =P17+U17+Z17+AE17+AJ17+AO17+AT17+AY17+BD17 -> 28346014 | L17: =Q17+V17+AA17+AF17+AK17+AP17+AU17+AZ17+BE17 -> 116395121 | M17: 4745253 | N17: 4340289 | O17: 4538764 | P17: 2551038 | Q17: 16175344 | R17: 1748325 | S17: 2043320 | T17: 2158687 | U17: 1749856 | V17: 7700188 | W17: 3573203 | X17: 2718297 | Y17: 2564658 | Z17: 2489893 | AA17: 11346051 | AB17: 1118791 | AC17: 2790564 | AD17: 1559017 | AE17: 2312732 | AF17: 7781104 | AG17: 14933880 | AH17: 11414499 | AI17: 9881724 | AJ17: 14972213 | AK17: 51202316 | AL17: 776352 | AM17: 1058442 | AN17: 974991 | AO17: 754175 | AP17: 3563960 | AQ17: 1938717 | AR17: 2307353 | AS17: 1951944 | AT17: 2128978 | AU17: 8326992 | AV17: 313370 | AW17: 292261 | AX17: 329881 | AY17: 170358 | AZ17: 1105870 | BA17: 3344655 | BB17: 2418280 | BC17: 2213590 | BD17: 1216771 | BE17: 9193296 | BF17: =BK17+BP17+BU17+BZ17+CE17 -> 1116895 | BG17: =BL17+BQ17+BV17+CA17+CF17 -> 1001235 | BH17: =BM17+BR17+BW17+CB17+CG17 -> 1164690 | BI17: =BN17+BS17+BX17+CC17+CH17 -> 1085254 | BJ17: =BO17+BT17+BY17+CD17+CI17 -> 4368074 | BK17: 86160 | BL17: 96183 | BM17: 117405 | BN17: 130957 | BO17: 430705 | BP17: 236409 | BQ17: 233385 | BR17: 157336 | BS17: 181717 | BT17: 808847 | BU17: 566577 | BV17: 430840 | BW17: 717767 | BX17: 637053 | BY17: 2352237 | BZ17: 139330 | CA17: 158470 | CB17: 146013 | CC17: 90482 | CD17: 534295 | CE17: 88419 | CF17: 82357 | CG17: 26169 | CH17: 45045 | CI17: 241990
A18: DIMOO | B18: 潮流玩具 | C18: =H18+BF18 -> 6505702 | D18: =I18+BG18 -> 4868835 | E18: =J18+BH18 -> 11551876 | F18: =K18+BI18 -> 9873962 | G18: =L18+BJ18 -> 32800375 | H18: =M18+R18+W18+AB18+AG18+AL18+AQ18+AV18+BA18 -> 6000659 | I18: =N18+S18+X18+AC18+AH18+AM18+AR18+AW18+BB18 -> 4449669 | J18: =O18+T18+Y18+AD18+AI18+AN18+AS18+AX18+BC18 -> 10799750 | K18: =P18+U18+Z18+AE18+AJ18+AO18+AT18+AY18+BD18 -> 9088218 | L18: =Q18+V18+AA18+AF18+AK18+AP18+AU18+AZ18+BE18 -> 30338296 | M18: 764119 | N18: 604233 | O18: 1112858 | P18: 1108510 | Q18: 3589720 | R18: 391801 | S18: 341518 | T18: 878718 | U18: 886440 | V18: 2498477 | W18: 469707 | X18: 269723 | Y18: 919912 | Z18: 571767 | AA18: 2231109 | AB18: 234135 | AC18: 519452 | AD18: 2099685 | AE18: 1175639 | AF18: 4028911 | AG18: 1806360 | AH18: 1017348 | AI18: 3293977 | AJ18: 2703454 | AK18: 8821139 | AL18: 205875 | AM18: 208919 | AN18: 349254 | AO18: 300774 | AP18: 1064822 | AQ18: 1037424 | AR18: 721594 | AS18: 1424055 | AT18: 1192144 | AU18: 4375217 | AV18: 143142 | AW18: 60497 | AX18: 64404 | AY18: 119538 | AZ18: 387581 | BA18: 948096 | BB18: 706385 | BC18: 656887 | BD18: 1029952 | BE18: 3341320 | BF18: =BK18+BP18+BU18+BZ18+CE18 -> 505043 | BG18: =BL18+BQ18+BV18+CA18+CF18 -> 419166 | BH18: =BM18+BR18+BW18+CB18+CG18 -> 752126 | BI18: =BN18+BS18+BX18+CC18+CH18 -> 785744 | BJ18: =BO18+BT18+BY18+CD18+CI18 -> 2462079 | BK18: 28825 | BL18: 27051 | BM18: 59803 | BN18: 51358 | BO18: 167037 | BP18: 253754 | BQ18: 226886 | BR18: 240519 | BS18: 301209 | BT18: 1022368 | BU18: 140867 | BV18: 121617 | BW18: 362352 | BX18: 344905 | BY18: 969741 | BZ18: 41773 | CA18: 21781 | CB18: 53750 | CC18: 55083 | CD18: 172387 | CE18: 39824 | CF18: 21831 | CG18: 35702 | CH18: 33189 | CI18: 130546
B19: 潮流周边 | C19: =H19+BF19 -> 2467337 | D19: =I19+BG19 -> 1667976 | E19: =J19+BH19 -> 4614976 | F19: =K19+BI19 -> 4214571 | G19: =L19+BJ19 -> 12964860 | H19: =M19+R19+W19+AB19+AG19+AL19+AQ19+AV19+BA19 -> 2331991 | I19: =N19+S19+X19+AC19+AH19+AM19+AR19+AW19+BB19 -> 1496750 | J19: =O19+T19+Y19+AD19+AI19+AN19+AS19+AX19+BC19 -> 4478426 | K19: =P19+U19+Z19+AE19+AJ19+AO19+AT19+AY19+BD19 -> 4082611 | L19: =Q19+V19+AA19+AF19+AK19+AP19+AU19+AZ19+BE19 -> 12389778 | M19: 187175 | N19: 113587 | O19: 309596 | P19: 436438 | Q19: 1046796 | R19: 73318 | S19: 40348 | T19: 246462 | U19: 202170 | V19: 562298 | W19: 381338 | X19: 141488 | Y19: 333485 | Z19: 637914 | AA19: 1494225 | AB19: 183994 | AC19: 60221 | AD19: 615340 | AE19: 452294 | AF19: 1311849 | AG19: 1001554 | AH19: 758781 | AI19: 2473501 | AJ19: 1628656 | AK19: 5862492 | AL19: 46995 | AM19: 28610 | AN19: 60879 | AO19: 62194 | AP19: 198678 | AQ19: 123618 | AR19: 153777 | AS19: 234160 | AT19: 257562 | AU19: 769117 | AV19: 35355 | AW19: 20614 | AX19: 10147 | AY19: 32766 | AZ19: 98882 | BA19: 298644 | BB19: 179324 | BC19: 194856 | BD19: 372617 | BE19: 1045441 | BF19: =BK19+BP19+BU19+BZ19+CE19 -> 135346 | BG19: =BL19+BQ19+BV19+CA19+CF19 -> 171226 | BH19: =BM19+BR19+BW19+CB19+CG19 -> 136550 | BI19: =BN19+BS19+BX19+CC19+CH19 -> 131960 | BJ19: =BO19+BT19+BY19+CD19+CI19 -> 575082 | BK19: 4685 | BL19: 9901 | BM19: 19427 | BN19: 13959 | BO19: 47972 | BP19: 49495 | BQ19: 61922 | BR19: 37519 | BS19: 35339 | BT19: 184275 | BU19: 74766 | BV19: 87735 | BW19: 63326 | BX19: 63025 | BY19: 288852 | BZ19: 4810 | CA19: 7534 | CB19: 14292 | CC19: 19320 | CD19: 45956 | CE19: 1590 | CF19: 4134 | CG19: 1986 | CH19: 317 | CI19: 8027
B20: 毛绒玩具 | C20: =H20+BF20 -> 739703 | D20: =I20+BG20 -> 547602 | E20: =J20+BH20 -> 13430079 | F20: =K20+BI20 -> 17046884 | G20: =L20+BJ20 -> 31764268 | H20: =M20+R20+W20+AB20+AG20+AL20+AQ20+AV20+BA20 -> 709416 | I20: =N20+S20+X20+AC20+AH20+AM20+AR20+AW20+BB20 -> 522119 | J20: =O20+T20+Y20+AD20+AI20+AN20+AS20+AX20+BC20 -> 13107127 | K20: =P20+U20+Z20+AE20+AJ20+AO20+AT20+AY20+BD20 -> 16681734 | L20: =Q20+V20+AA20+AF20+AK20+AP20+AU20+AZ20+BE20 -> 31020396 | M20: 91013 | N20: 30005 | O20: 281887 | P20: 1296854 | Q20: 1699759 | R20: 30242 | S20: 31921 | T20: 1165636 | U20: 1045948 | V20: 2273747 | W20: 92360 | X20: 58679 | Y20: 200928 | Z20: 2105889 | AA20: 2457856 | AB20: 23979 | AC20: 31694 | AD20: 416422 | AE20: 1247069 | AF20: 1719164 | AG20: 277481 | AH20: 251165 | AI20: 9969509 | AJ20: 7487701 | AK20: 17985856 | AL20: 18057 | AM20: 11932 | AN20: 253875 | AO20: 220549 | AP20: 504413 | AQ20: 27141 | AR20: 3895 | AS20: 722688 | AT20: 1785310 | AU20: 2539034 | AV20: 11492 | AW20: 8659 | AX20: 5734 | AY20: 131670 | AZ20: 157555 | BA20: 137651 | BB20: 94169 | BC20: 90448 | BD20: 1360744 | BE20: 1683012 | BF20: =BK20+BP20+BU20+BZ20+CE20 -> 30287 | BG20: =BL20+BQ20+BV20+CA20+CF20 -> 25483 | BH20: =BM20+BR20+BW20+CB20+CG20 -> 322952 | BI20: =BN20+BS20+BX20+CC20+CH20 -> 365150 | BJ20: =BO20+BT20+BY20+CD20+CI20 -> 743872 | BK20: 498 | BM20: 88247 | BN20: 96612 | BO20: 185357 | BP20: 15993 | BQ20: 21896 | BR20: 76634 | BS20: 86086 | BT20: 200609 | BU20: 13796 | BV20: 3587 | BW20: 129128 | BX20: 121991 | BY20: 268502 | CB20: 28943 | CC20: 60461 | CD20: 89404
B21: 收藏玩具 | C21: =H21+BF21 -> 126130 | D21: =I21+BG21 -> 83459 | E21: =J21+BH21 -> 3151992 | F21: =K21+BI21 -> 1804562 | G21: =L21+BJ21 -> 5166143 | H21: =M21+R21+W21+AB21+AG21+AL21+AQ21+AV21+BA21 -> 110339 | I21: =N21+S21+X21+AC21+AH21+AM21+AR21+AW21+BB21 -> 55968 | J21: =O21+T21+Y21+AD21+AI21+AN21+AS21+AX21+BC21 -> 3136602 | K21: =P21+U21+Z21+AE21+AJ21+AO21+AT21+AY21+BD21 -> 1798766 | L21: =Q21+V21+AA21+AF21+AK21+AP21+AU21+AZ21+BE21 -> 5101675 | M21: 1299 | N21: 2598 | O21: 197448 | P21: 193716 | Q21: 395061 | R21: 10197 | S21: 2599 | T21: 210909 | U21: 205242 | V21: 428947 | Y21: 302667 | Z21: 282425 | AA21: 585092 | AB21: 20195 | AE21: 264240 | AF21: 284435 | AI21: 2090633 | AJ21: 497296 | AK21: 2587929 | AL21: 9093 | AM21: 2598 | AN21: 109116 | AO21: 85238 | AP21: 206045 | AQ21: 48771 | AR21: 11691 | AS21: 211540 | AT21: 49669 | AU21: 321671 | AW21: 10998 | AY21: 27279 | AZ21: 38277 | BA21: 20784 | BB21: 25484 | BC21: 14289 | BD21: 193661 | BE21: 254218 | BF21: =BK21+BP21+BU21+BZ21+CE21 -> 15791 | BG21: =BL21+BQ21+BV21+CA21+CF21 -> 27491 | BH21: =BM21+BR21+BW21+CB21+CG21 -> 15390 | BI21: =BN21+BS21+BX21+CC21+CH21 -> 5796 | BJ21: =BO21+BT21+BY21+CD21+CI21 -> 64468 | BK21: 4497 | BL21: 2598 | BN21: 2598 | BO21: 9693 | BP21: 6298 | BQ21: 2598 | BR21: 5196 | BT21: 14092 | BU21: 4996 | BV21: 17296 | BW21: 10194 | BX21: 1299 | BY21: 33785 | CA21: 4999 | CC21: 1899 | CD21: 6898
A22: DIMOO 汇总 | C22: =H22+BF22 -> 9838872 | D22: =I22+BG22 -> 7167872 | E22: =J22+BH22 -> 32748923 | F22: =K22+BI22 -> 32939979 | G22: =L22+BJ22 -> 82695646 | H22: =M22+R22+W22+AB22+AG22+AL22+AQ22+AV22+BA22 -> 9152405 | I22: =N22+S22+X22+AC22+AH22+AM22+AR22+AW22+BB22 -> 6524506 | J22: =O22+T22+Y22+AD22+AI22+AN22+AS22+AX22+BC22 -> 31521905 | K22: =P22+U22+Z22+AE22+AJ22+AO22+AT22+AY22+BD22 -> 31651329 | L22: =Q22+V22+AA22+AF22+AK22+AP22+AU22+AZ22+BE22 -> 78850145 | M22: 1043606 | N22: 750423 | O22: 1901789 | P22: 3035518 | Q22: 6731336 | R22: 505558 | S22: 416386 | T22: 2501725 | U22: 2339800 | V22: 5763469 | W22: 943405 | X22: 469890 | Y22: 1756992 | Z22: 3597995 | AA22: 6768282 | AB22: 462303 | AC22: 611367 | AD22: 3131447 | AE22: 3139242 | AF22: 7344359 | AG22: 3085395 | AH22: 2027294 | AI22: 17827620 | AJ22: 12317107 | AK22: 35257416 | AL22: 280020 | AM22: 252059 | AN22: 773124 | AO22: 668755 | AP22: 1973958 | AQ22: 1236954 | AR22: 890957 | AS22: 2592443 | AT22: 3284685 | AU22: 8005039 | AV22: 189989 | AW22: 100768 | AX22: 80285 | AY22: 311253 | AZ22: 682295 | BA22: 1405175 | BB22: 1005362 | BC22: 956480 | BD22: 2956974 | BE22: 6323991 | BF22: =BK22+BP22+BU22+BZ22+CE22 -> 686467 | BG22: =BL22+BQ22+BV22+CA22+CF22 -> 643366 | BH22: =BM22+BR22+BW22+CB22+CG22 -> 1227018 | BI22: =BN22+BS22+BX22+CC22+CH22 -> 1288650 | BJ22: =BO22+BT22+BY22+CD22+CI22 -> 3845501 | BK22: 38505 | BL22: 39550 | BM22: 167477 | BN22: 164527 | BO22: 410059 | BP22: 325540 | BQ22: 313302 | BR22: 359868 | BS22: 422634 | BT22: 1421344 | BU22: 234425 | BV22: 230235 | BW22: 565000 | BX22: 531220 | BY22: 1560880 | BZ22: 46583 | CA22: 34314 | CB22: 96985 | CC22: 136763 | CD22: 314645 | CE22: 41414 | CF22: 25965 | CG22: 37688 | CH22: 33506 | CI22: 138573
A23: SKULLPANDA | B23: 潮流玩具 | C23: =H23+BF23 -> 8978315 | D23: =I23+BG23 -> 9995612 | E23: =J23+BH23 -> 7589134 | F23: =K23+BI23 -> 10442721 | G23: =L23+BJ23 -> 37005782 | H23: =M23+R23+W23+AB23+AG23+AL23+AQ23+AV23+BA23 -> 7468360 | I23: =N23+S23+X23+AC23+AH23+AM23+AR23+AW23+BB23 -> 8509318 | J23: =O23+T23+Y23+AD23+AI23+AN23+AS23+AX23+BC23 -> 6025381 | K23: =P23+U23+Z23+AE23+AJ23+AO23+AT23+AY23+BD23 -> 8536765 | L23: =Q23+V23+AA23+AF23+AK23+AP23+AU23+AZ23+BE23 -> 30539824 | M23: 1631642 | N23: 1762863 | O23: 1087556 | P23: 1928779 | Q23: 6410840 | R23: 653084 | S23: 1062474 | T23: 660167 | U23: 983394 | V23: 3359119 | W23: 333089 | X23: 403997 | Y23: 684672 | Z23: 668295 | AA23: 2090053 | AB23: 202633 | AC23: 222133 | AD23: 592649 | AE23: 811294 | AF23: 1828709 | AG23: 2012982 | AH23: 2555525 | AI23: 936281 | AJ23: 1827261 | AK23: 7332049 | AL23: 285771 | AM23: 410593 | AN23: 284160 | AO23: 408934 | AP23: 1389458 | AQ23: 1185665 | AR23: 809542 | AS23: 600789 | AT23: 801010 | AU23: 3397006 | AV23: 119247 | AW23: 153563 | AX23: 135574 | AY23: 45987 | AZ23: 454371 | BA23: 1044247 | BB23: 1128628 | BC23: 1043533 | BD23: 1061811 | BE23: 4278219 | BF23: =BK23+BP23+BU23+BZ23+CE23 -> 1509955 | BG23: =BL23+BQ23+BV23+CA23+CF23 -> 1486294 | BH23: =BM23+BR23+BW23+CB23+CG23 -> 1563753 | BI23: =BN23+BS23+BX23+CC23+CH23 -> 1905956 | BJ23: =BO23+BT23+BY23+CD23+CI23 -> 6465958 | BK23: 89061 | BL23: 81213 | BM23: 95946 | BN23: 136193 | BO23: 402413 | BP23: 460679 | BQ23: 537417 | BR23: 507382 | BS23: 622093 | BT23: 2127571 | BU23: 713749 | BV23: 614136 | BW23: 697656 | BX23: 812325 | BY23: 2837866 | BZ23: 129640 | CA23: 150650 | CB23: 152574 | CC23: 204500 | CD23: 637364 | CE23: 116826 | CF23: 102878 | CG23: 110195 | CH23: 130845 | CI23: 460744
B24: 潮流周边 | C24: =H24+BF24 -> 933297 | D24: =I24+BG24 -> 626517 | E24: =J24+BH24 -> 492318 | F24: =K24+BI24 -> 1297585 | G24: =L24+BJ24 -> 3349717 | H24: =M24+R24+W24+AB24+AG24+AL24+AQ24+AV24+BA24 -> 840583 | I24: =N24+S24+X24+AC24+AH24+AM24+AR24+AW24+BB24 -> 554922 | J24: =O24+T24+Y24+AD24+AI24+AN24+AS24+AX24+BC24 -> 427671 | K24: =P24+U24+Z24+AE24+AJ24+AO24+AT24+AY24+BD24 -> 1130591 | L24: =Q24+V24+AA24+AF24+AK24+AP24+AU24+AZ24+BE24 -> 2953767 | M24: 23205 | N24: 16510 | O24: 11825 | P24: 91906 | Q24: 143446 | R24: 25596 | S24: 16464 | T24: 20510 | U24: 29171 | V24: 91741 | W24: 27671 | X24: 20757 | Y24: 24745 | Z24: 89353 | AA24: 162526 | AB24: 78022 | AC24: 69445 | AD24: 38752 | AE24: 156324 | AF24: 342543 | AG24: 520970 | AH24: 306551 | AI24: 215572 | AJ24: 483642 | AK24: 1526735 | AL24: 28449 | AM24: 28666 | AN24: 34337 | AO24: 56666 | AP24: 148118 | AQ24: 35027 | AR24: 33862 | AS24: 28533 | AT24: 86684 | AU24: 184106 | AV24: 10983 | AW24: 7738 | AX24: 6983 | AY24: 13053 | AZ24: 38757 | BA24: 90660 | BB24: 54929 | BC24: 46414 | BD24: 123792 | BE24: 315795 | BF24: =BK24+BP24+BU24+BZ24+CE24 -> 92714 | BG24: =BL24+BQ24+BV24+CA24+CF24 -> 71595 | BH24: =BM24+BR24+BW24+CB24+CG24 -> 64647 | BI24: =BN24+BS24+BX24+CC24+CH24 -> 166994 | BJ24: =BO24+BT24+BY24+CD24+CI24 -> 395950 | BK24: 3356 | BL24: 4589 | BM24: 4833 | BN24: 10528 | BO24: 23306 | BP24: 27359 | BQ24: 17465 | BR24: 8667 | BS24: 30743 | BT24: 84234 | BU24: 46418 | BV24: 42697 | BW24: 43416 | BX24: 101431 | BY24: 233962 | BZ24: 7424 | CA24: 5704 | CB24: 4577 | CC24: 16908 | CD24: 34613 | CE24: 8157 | CF24: 1140 | CG24: 3154 | CH24: 7384 | CI24: 19835
B25: 毛绒玩具 | C25: =H25+BF25 -> 4455790 | D25: =I25+BG25 -> 4576468 | E25: =J25+BH25 -> 7361800 | F25: =K25+BI25 -> 8904549 | G25: =L25+BJ25 -> 25298607 | H25: =M25+R25+W25+AB25+AG25+AL25+AQ25+AV25+BA25 -> 4134870 | I25: =N25+S25+X25+AC25+AH25+AM25+AR25+AW25+BB25 -> 3156503 | J25: =O25+T25+Y25+AD25+AI25+AN25+AS25+AX25+BC25 -> 5198885 | K25: =P25+U25+Z25+AE25+AJ25+AO25+AT25+AY25+BD25 -> 6907115 | L25: =Q25+V25+AA25+AF25+AK25+AP25+AU25+AZ25+BE25 -> 19397373 | M25: 257147 | N25: 253834 | O25: 462544 | P25: 1609264 | Q25: 2582789 | R25: 334945 | S25: 561783 | T25: 520062 | U25: 755604 | V25: 2172394 | W25: 21512 | X25: 607101 | Y25: 763414 | Z25: 788763 | AA25: 2180790 | AB25: 9555 | AC25: 586 | AD25: 2344 | AE25: 1071544 | AF25: 1084029 | AG25: 3056070 | AH25: 1268203 | AI25: 2760904 | AJ25: 1364321 | AK25: 8449498 | AL25: 29007 | AM25: 85141 | AN25: 171315 | AO25: 464581 | AP25: 750044 | AQ25: 300570 | AR25: 130032 | AS25: 441954 | AT25: 492651 | AU25: 1365207 | AV25: 69 | AW25: 33927 | AX25: 58953 | AY25: 25413 | AZ25: 118362 | BA25: 125995 | BB25: 215896 | BC25: 17395 | BD25: 334974 | BE25: 694260 | BF25: =BK25+BP25+BU25+BZ25+CE25 -> 320920 | BG25: =BL25+BQ25+BV25+CA25+CF25 -> 1419965 | BH25: =BM25+BR25+BW25+CB25+CG25 -> 2162915 | BI25: =BN25+BS25+BX25+CC25+CH25 -> 1997434 | BJ25: =BO25+BT25+BY25+CD25+CI25 -> 5901234 | BK25: 11112 | BL25: 211032 | BM25: 162094 | BN25: 127206 | BO25: 511444 | BP25: 288309 | BQ25: 356225 | BR25: 428900 | BS25: 406444 | BT25: 1479878 | BU25: 7720 | BV25: 678697 | BW25: 1356826 | BX25: 1245538 | BY25: 3288781 | BZ25: 11985 | CA25: 173528 | CB25: 86250 | CC25: 94406 | CD25: 366169 | CE25: 1794 | CF25: 483 | CG25: 128845 | CH25: 123840 | CI25: 254962
B26: 收藏玩具 | C26: =H26+BF26 -> 278340 | D26: =I26+BG26 -> 299844 | E26: =J26+BH26 -> 231882 | F26: =K26+BI26 -> 168913 | G26: =L26+BJ26 -> 978979 | H26: =M26+R26+W26+AB26+AG26+AL26+AQ26+AV26+BA26 -> 252350 | I26: =N26+S26+X26+AC26+AH26+AM26+AR26+AW26+BB26 -> 246861 | J26: =O26+T26+Y26+AD26+AI26+AN26+AS26+AX26+BC26 -> 187397 | K26: =P26+U26+Z26+AE26+AJ26+AO26+AT26+AY26+BD26 -> 144422 | L26: =Q26+V26+AA26+AF26+AK26+AP26+AU26+AZ26+BE26 -> 831030 | R26: 17988 | S26: 6999 | T26: 11992 | U26: 14990 | V26: 51969 | W26: 24987 | X26: 13491 | AA26: 38478 | AC26: 25494 | AD26: 15497 | AE26: 1499 | AF26: 42490 | AG26: 135913 | AH26: 131912 | AI26: 101932 | AJ26: 67455 | AK26: 437212 | AL26: 16996 | AM26: 12995 | AN26: 2998 | AO26: 19994 | AP26: 52983 | AQ26: 16489 | AR26: 27985 | AS26: 5996 | AT26: 19994 | AU26: 70464 | AV26: 11496 | AW26: 1499 | AX26: 22496 | AY26: 8498 | AZ26: 43989 | BA26: 28481 | BB26: 26486 | BC26: 26486 | BD26: 11992 | BE26: 93445 | BF26: =BK26+BP26+BU26+BZ26+CE26 -> 25990 | BG26: =BL26+BQ26+BV26+CA26+CF26 -> 52983 | BH26: =BM26+BR26+BW26+CB26+CG26 -> 44485 | BI26: =BN26+BS26+BX26+CC26+CH26 -> 24491 | BJ26: =BO26+BT26+BY26+CD26+CI26 -> 147949 | BP26: 8498 | BQ26: 25494 | BR26: 8498 | BS26: 9997 | BT26: 52487 | BU26: 10493 | BV26: 15993 | BW26: 32989 | BX26: 14494 | BY26: 73969 | BZ26: 6999 | CA26: 11496 | CB26: 2998 | CD26: 21493
B27: 珠宝首饰 | C27: =H27+BF27 -> 8956 | D27: =I27+BG27 -> 0 | E27: =J27+BH27 -> 0 | F27: =K27+BI27 -> 0 | G27: =L27+BJ27 -> 8956 | H27: =M27+R27+W27+AB27+AG27+AL27+AQ27+AV27+BA27 -> 8956 | I27: =N27+S27+X27+AC27+AH27+AM27+AR27+AW27+BB27 -> 0 | J27: =O27+T27+Y27+AD27+AI27+AN27+AS27+AX27+BC27 -> 0 | K27: =P27+U27+Z27+AE27+AJ27+AO27+AT27+AY27+BD27 -> 0 | L27: =Q27+V27+AA27+AF27+AK27+AP27+AU27+AZ27+BE27 -> 8956 | AG27: 8956 | AK27: 8956 | BF27: =BK27+BP27+BU27+BZ27+CE27 -> 0 | BG27: =BL27+BQ27+BV27+CA27+CF27 -> 0 | BH27: =BM27+BR27+BW27+CB27+CG27 -> 0 | BI27: =BN27+BS27+BX27+CC27+CH27 -> 0 | BJ27: =BO27+BT27+BY27+CD27+CI27 -> 0
A28: SKULLPANDA 汇总 | C28: =H28+BF28 -> 14654698 | D28: =I28+BG28 -> 15498441 | E28: =J28+BH28 -> 15675134 | F28: =K28+BI28 -> 20813768 | G28: =L28+BJ28 -> 66642041 | H28: =M28+R28+W28+AB28+AG28+AL28+AQ28+AV28+BA28 -> 12705119 | I28: =N28+S28+X28+AC28+AH28+AM28+AR28+AW28+BB28 -> 12467604 | J28: =O28+T28+Y28+AD28+AI28+AN28+AS28+AX28+BC28 -> 11839334 | K28: =P28+U28+Z28+AE28+AJ28+AO28+AT28+AY28+BD28 -> 16718893 | L28: =Q28+V28+AA28+AF28+AK28+AP28+AU28+AZ28+BE28 -> 53730950 | M28: 1911994 | N28: 2033207 | O28: 1561925 | P28: 3629949 | Q28: 9137075 | R28: 1031613 | S28: 1647720 | T28: 1212731 | U28: 1783159 | V28: 5675223 | W28: 407259 | X28: 1045346 | Y28: 1472831 | Z28: 1546411 | AA28: 4471847 | AB28: 290210 | AC28: 317658 | AD28: 649242 | AE28: 2040661 | AF28: 3297771 | AG28: 5734891 | AH28: 4262191 | AI28: 4014689 | AJ28: 3742679 | AK28: 17754450 | AL28: 360223 | AM28: 537395 | AN28: 492810 | AO28: 950175 | AP28: 2340603 | AQ28: 1537751 | AR28: 1001421 | AS28: 1077272 | AT28: 1400339 | AU28: 5016783 | AV28: 141795 | AW28: 196727 | AX28: 224006 | AY28: 92951 | AZ28: 655479 | BA28: 1289383 | BB28: 1425939 | BC28: 1133828 | BD28: 1532569 | BE28: 5381719 | BF28: =BK28+BP28+BU28+BZ28+CE28 -> 1949579 | BG28: =BL28+BQ28+BV28+CA28+CF28 -> 3030837 | BH28: =BM28+BR28+BW28+CB28+CG28 -> 3835800 | BI28: =BN28+BS28+BX28+CC28+CH28 -> 4094875 | BJ28: =BO28+BT28+BY28+CD28+CI28 -> 12911091 | BK28: 103529 | BL28: 296834 | BM28: 262873 | BN28: 273927 | BO28: 937163 | BP28: 784845 | BQ28: 936601 | BR28: 953447 | BS28: 1069277 | BT28: 3744170 | BU28: 778380 | BV28: 1351523 | BW28: 2130887 | BX28: 2173788 | BY28: 6434578 | BZ28: 156048 | CA28: 341378 | CB28: 246399 | CC28: 315814 | CD28: 1059639 | CE28: 126777 | CF28: 104501 | CG28: 242194 | CH28: 262069 | CI28: 735541
A29: HIRONO | B29: 潮流玩具 | C29: =H29+BF29 -> 13565159 | D29: =I29+BG29 -> 13790838 | E29: =J29+BH29 -> 12274924 | F29: =K29+BI29 -> 17932653 | G29: =L29+BJ29 -> 57563574 | H29: =M29+R29+W29+AB29+AG29+AL29+AQ29+AV29+BA29 -> 11883349 | I29: =N29+S29+X29+AC29+AH29+AM29+AR29+AW29+BB29 -> 12021525 | J29: =O29+T29+Y29+AD29+AI29+AN29+AS29+AX29+BC29 -> 10423369 | K29: =P29+U29+Z29+AE29+AJ29+AO29+AT29+AY29+BD29 -> 15528561 | L29: =Q29+V29+AA29+AF29+AK29+AP29+AU29+AZ29+BE29 -> 49856804 | M29: 1652800 | N29: 1593374 | O29: 1543593 | P29: 1477618 | Q29: 6267385 | R29: 734166 | S29: 631996 | T29: 642910 | U29: 1359684 | V29: 3368756 | W29: 2025796 | X29: 1895489 | Y29: 1722666 | Z29: 1958380 | AA29: 7602331 | AB29: 277432 | AC29: 825232 | AD29: 741898 | AE29: 1050387 | AF29: 2894949 | AG29: 3667980 | AH29: 3410897 | AI29: 2555165 | AJ29: 5596764 | AK29: 15230806 | AL29: 557242 | AM29: 755125 | AN29: 732973 | AO29: 1256616 | AP29: 3301956 | AQ29: 1307948 | AR29: 1118152 | AS29: 1190293 | AT29: 1910708 | AU29: 5527101 | AV29: 179302 | AW29: 154798 | AX29: 86620 | AY29: 90050 | AZ29: 510770 | BA29: 1480683 | BB29: 1636462 | BC29: 1207251 | BD29: 828354 | BE29: 5152750 | BF29: =BK29+BP29+BU29+BZ29+CE29 -> 1681810 | BG29: =BL29+BQ29+BV29+CA29+CF29 -> 1769313 | BH29: =BM29+BR29+BW29+CB29+CG29 -> 1851555 | BI29: =BN29+BS29+BX29+CC29+CH29 -> 2404092 | BJ29: =BO29+BT29+BY29+CD29+CI29 -> 7706770 | BK29: 130738 | BL29: 132621 | BM29: 138552 | BN29: 122912 | BO29: 524823 | BP29: 622839 | BQ29: 692700 | BR29: 549402 | BS29: 772495 | BT29: 2637436 | BU29: 672780 | BV29: 618492 | BW29: 848357 | BX29: 1138833 | BY29: 3278462 | BZ29: 183567 | CA29: 180415 | CB29: 163773 | CC29: 196000 | CD29: 723755 | CE29: 71886 | CF29: 145085 | CG29: 151471 | CH29: 173852 | CI29: 542294
B30: 潮流周边 | C30: =H30+BF30 -> 86682 | D30: =I30+BG30 -> 45995 | E30: =J30+BH30 -> 26561 | F30: =K30+BI30 -> 2908177 | G30: =L30+BJ30 -> 3067415 | H30: =M30+R30+W30+AB30+AG30+AL30+AQ30+AV30+BA30 -> 78408 | I30: =N30+S30+X30+AC30+AH30+AM30+AR30+AW30+BB30 -> 42354 | J30: =O30+T30+Y30+AD30+AI30+AN30+AS30+AX30+BC30 -> 22960 | K30: =P30+U30+Z30+AE30+AJ30+AO30+AT30+AY30+BD30 -> 2806160 | L30: =Q30+V30+AA30+AF30+AK30+AP30+AU30+AZ30+BE30 -> 2949882 | M30: 258 | N30: 258 | P30: 156899 | Q30: 157415 | U30: 121198 | V30: 121198 | Z30: 443813 | AA30: 443813 | AB30: 22007 | AC30: 22892 | AD30: 14524 | AE30: 94065 | AF30: 153488 | AG30: 46256 | AH30: 11269 | AI30: 3245 | AJ30: 1764665 | AK30: 1825435 | AM30: 138 | AO30: 86783 | AP30: 86921 | AQ30: 2193 | AR30: 2967 | AS30: 2193 | AT30: 137450 | AU30: 144803 | AV30: 4018 | AW30: 2699 | AX30: 1687 | AY30: 1041 | AZ30: 9445 | BA30: 3676 | BB30: 2131 | BC30: 1311 | BD30: 246 | BE30: 7364 | BF30: =BK30+BP30+BU30+BZ30+CE30 -> 8274 | BG30: =BL30+BQ30+BV30+CA30+CF30 -> 3641 | BH30: =BM30+BR30+BW30+CB30+CG30 -> 3601 | BI30: =BN30+BS30+BX30+CC30+CH30 -> 102017 | BJ30: =BO30+BT30+BY30+CD30+CI30 -> 117533 | BK30: 3599 | BL30: 708 | BM30: 1121 | BN30: 8180 | BO30: 13608 | BP30: 590 | BQ30: 649 | BR30: 531 | BS30: 31865 | BT30: 33635 | BU30: 4085 | BV30: 2284 | BW30: 1949 | BX30: 53776 | BY30: 62094 | CC30: 6753 | CD30: 6753 | CH30: 1443 | CI30: 1443
B31: 收藏玩具 | C31: =H31+BF31 -> 23994 | D31: =I31+BG31 -> 341414 | E31: =J31+BH31 -> 91977 | F31: =K31+BI31 -> 63984 | G31: =L31+BJ31 -> 521369 | H31: =M31+R31+W31+AB31+AG31+AL31+AQ31+AV31+BA31 -> 23994 | I31: =N31+S31+X31+AC31+AH31+AM31+AR31+AW31+BB31 -> 327918 | J31: =O31+T31+Y31+AD31+AI31+AN31+AS31+AX31+BC31 -> 79980 | K31: =P31+U31+Z31+AE31+AJ31+AO31+AT31+AY31+BD31 -> 59985 | L31: =Q31+V31+AA31+AF31+AK31+AP31+AU31+AZ31+BE31 -> 491877 | M31: 11997 | Q31: 11997 | R31: 11997 | V31: 11997 | AH31: 327918 | AI31: 79980 | AK31: 407898 | AT31: 59985 | AU31: 59985 | BF31: =BK31+BP31+BU31+BZ31+CE31 -> 0 | BG31: =BL31+BQ31+BV31+CA31+CF31 -> 13496 | BH31: =BM31+BR31+BW31+CB31+CG31 -> 11997 | BI31: =BN31+BS31+BX31+CC31+CH31 -> 3999 | BJ31: =BO31+BT31+BY31+CD31+CI31 -> 29492 | BQ31: 5498 | BR31: 3999 | BS31: 3999 | BT31: 13496 | BV31: 7998 | BW31: 7998 | BY31: 15996
B32: 组合产品 | C32: =H32+BF32 -> 510947 | D32: =I32+BG32 -> 396538 | E32: =J32+BH32 -> 167121 | F32: =K32+BI32 -> 97038 | G32: =L32+BJ32 -> 1171644 | H32: =M32+R32+W32+AB32+AG32+AL32+AQ32+AV32+BA32 -> 494175 | I32: =N32+S32+X32+AC32+AH32+AM32+AR32+AW32+BB32 -> 370781 | J32: =O32+T32+Y32+AD32+AI32+AN32+AS32+AX32+BC32 -> 129983 | K32: =P32+U32+Z32+AE32+AJ32+AO32+AT32+AY32+BD32 -> 81464 | L32: =Q32+V32+AA32+AF32+AK32+AP32+AU32+AZ32+BE32 -> 1076403 | M32: 34143 | N32: 56905 | O32: 26356 | P32: 25757 | Q32: 143161 | R32: 7787 | S32: 17371 | T32: 1198 | V32: 26356 | W32: 11980 | AA32: 11980 | AC32: 131181 | AE32: 599 | AF32: 131780 | AG32: 338435 | AH32: 88053 | AI32: 58702 | AJ32: 44925 | AK32: 530115 | AL32: 10782 | AM32: 8985 | AN32: 6589 | AP32: 26356 | AQ32: 28752 | AR32: 10782 | AS32: 11381 | AU32: 50915 | AV32: 8985 | AW32: 13777 | AX32: 4193 | AZ32: 26955 | BA32: 53311 | BB32: 43727 | BC32: 21564 | BD32: 10183 | BE32: 128785 | BF32: =BK32+BP32+BU32+BZ32+CE32 -> 16772 | BG32: =BL32+BQ32+BV32+CA32+CF32 -> 25757 | BH32: =BM32+BR32+BW32+CB32+CG32 -> 37138 | BI32: =BN32+BS32+BX32+CC32+CH32 -> 15574 | BJ32: =BO32+BT32+BY32+CD32+CI32 -> 95241 | BK32: 7787 | BO32: 7787 | BQ32: 20366 | BR32: 16772 | BS32: 9584 | BT32: 46722 | BW32: 20366 | BX32: 5990 | BY32: 26356 | BZ32: 8985 | CA32: 5391 | CD32: 14376
A33: HIRONO 汇总 | C33: =H33+BF33 -> 14186782 | D33: =I33+BG33 -> 14574785 | E33: =J33+BH33 -> 12560583 | F33: =K33+BI33 -> 21001852 | G33: =L33+BJ33 -> 62324002 | H33: =M33+R33+W33+AB33+AG33+AL33+AQ33+AV33+BA33 -> 12479926 | I33: =N33+S33+X33+AC33+AH33+AM33+AR33+AW33+BB33 -> 12762578 | J33: =O33+T33+Y33+AD33+AI33+AN33+AS33+AX33+BC33 -> 10656292 | K33: =P33+U33+Z33+AE33+AJ33+AO33+AT33+AY33+BD33 -> 18476170 | L33: =Q33+V33+AA33+AF33+AK33+AP33+AU33+AZ33+BE33 -> 54374966 | M33: 1699198 | N33: 1650537 | O33: 1569949 | P33: 1660274 | Q33: 6579958 | R33: 753950 | S33: 649367 | T33: 644108 | U33: 1480882 | V33: 3528307 | W33: 2037776 | X33: 1895489 | Y33: 1722666 | Z33: 2402193 | AA33: 8058124 | AB33: 299439 | AC33: 979305 | AD33: 756422 | AE33: 1145051 | AF33: 3180217 | AG33: 4052671 | AH33: 3838137 | AI33: 2697092 | AJ33: 7406354 | AK33: 17994254 | AL33: 568024 | AM33: 764248 | AN33: 739562 | AO33: 1343399 | AP33: 3415233 | AQ33: 1338893 | AR33: 1131901 | AS33: 1203867 | AT33: 2108143 | AU33: 5782804 | AV33: 192305 | AW33: 171274 | AX33: 92500 | AY33: 91091 | AZ33: 547170 | BA33: 1537670 | BB33: 1682320 | BC33: 1230126 | BD33: 838783 | BE33: 5288899 | BF33: =BK33+BP33+BU33+BZ33+CE33 -> 1706856 | BG33: =BL33+BQ33+BV33+CA33+CF33 -> 1812207 | BH33: =BM33+BR33+BW33+CB33+CG33 -> 1904291 | BI33: =BN33+BS33+BX33+CC33+CH33 -> 2525682 | BJ33: =BO33+BT33+BY33+CD33+CI33 -> 7949036 | BK33: 142124 | BL33: 133329 | BM33: 139673 | BN33: 131092 | BO33: 546218 | BP33: 623429 | BQ33: 719213 | BR33: 570704 | BS33: 817943 | BT33: 2731289 | BU33: 676865 | BV33: 628774 | BW33: 878670 | BX33: 1198599 | BY33: 3382908 | BZ33: 192552 | CA33: 185806 | CB33: 163773 | CC33: 202753 | CD33: 744884 | CE33: 71886 | CF33: 145085 | CG33: 151471 | CH33: 175295 | CI33: 543737
A34: DISNEY | B34: 潮流玩具 | C34: =H34+BF34 -> 8647080 | D34: =I34+BG34 -> 8746746 | E34: =J34+BH34 -> 9198016 | F34: =K34+BI34 -> 8351910 | G34: =L34+BJ34 -> 34943752 | H34: =M34+R34+W34+AB34+AG34+AL34+AQ34+AV34+BA34 -> 6923725 | I34: =N34+S34+X34+AC34+AH34+AM34+AR34+AW34+BB34 -> 6838217 | J34: =O34+T34+Y34+AD34+AI34+AN34+AS34+AX34+BC34 -> 7310429 | K34: =P34+U34+Z34+AE34+AJ34+AO34+AT34+AY34+BD34 -> 6722538 | L34: =Q34+V34+AA34+AF34+AK34+AP34+AU34+AZ34+BE34 -> 27794909 | M34: 1743467 | N34: 1581449 | O34: 1531807 | P34: 1609425 | Q34: 6466148 | R34: 1154077 | S34: 1091386 | T34: 1192110 | U34: 968057 | V34: 4405630 | W34: 328536 | X34: 347004 | Y34: 449241 | Z34: 367139 | AA34: 1491920 | AB34: 607993 | AC34: 993039 | AD34: 865998 | AE34: 813688 | AF34: 3280718 | AG34: 1631063 | AH34: 1364656 | AI34: 1492651 | AJ34: 1420798 | AK34: 5909168 | AL34: 144169 | AM34: 200886 | AN34: 168372 | AO34: 158347 | AP34: 671774 | AQ34: 625818 | AR34: 556495 | AS34: 607922 | AT34: 532648 | AU34: 2322883 | AV34: 105972 | AW34: 89984 | AX34: 125419 | AY34: 97408 | AZ34: 418783 | BA34: 582630 | BB34: 613318 | BC34: 876909 | BD34: 755028 | BE34: 2827885 | BF34: =BK34+BP34+BU34+BZ34+CE34 -> 1723355 | BG34: =BL34+BQ34+BV34+CA34+CF34 -> 1908529 | BH34: =BM34+BR34+BW34+CB34+CG34 -> 1887587 | BI34: =BN34+BS34+BX34+CC34+CH34 -> 1629372 | BJ34: =BO34+BT34+BY34+CD34+CI34 -> 7148843 | BK34: 78469 | BL34: 67179 | BM34: 87405 | BN34: 51029 | BO34: 284082 | BP34: 1148686 | BQ34: 1259419 | BR34: 1114276 | BS34: 838214 | BT34: 4360595 | BU34: 377746 | BV34: 449114 | BW34: 577539 | BX34: 612187 | BY34: 2016586 | BZ34: 85145 | CA34: 76131 | CB34: 86839 | CC34: 100679 | CD34: 348794 | CE34: 33309 | CF34: 56686 | CG34: 21528 | CH34: 27263 | CI34: 138786
B35: 毛绒玩具 | C35: =H35+BF35 -> 0 | D35: =I35+BG35 -> 291753 | E35: =J35+BH35 -> 3197106 | F35: =K35+BI35 -> 4505886 | G35: =L35+BJ35 -> 7994745 | H35: =M35+R35+W35+AB35+AG35+AL35+AQ35+AV35+BA35 -> 0 | I35: =N35+S35+X35+AC35+AH35+AM35+AR35+AW35+BB35 -> 291753 | J35: =O35+T35+Y35+AD35+AI35+AN35+AS35+AX35+BC35 -> 2972772 | K35: =P35+U35+Z35+AE35+AJ35+AO35+AT35+AY35+BD35 -> 4197501 | L35: =Q35+V35+AA35+AF35+AK35+AP35+AU35+AZ35+BE35 -> 7462026 | O35: 190377 | P35: 1026531 | Q35: 1216908 | S35: 100386 | T35: 307989 | U35: 529551 | V35: 937926 | Y35: 286902 | Z35: 488268 | AA35: 775170 | AC35: 80586 | AD35: 151272 | AE35: 418671 | AF35: 650529 | AH35: 93753 | AI35: 1052568 | AJ35: 1188990 | AK35: 2335311 | AM35: 17028 | AN35: 22275 | AO35: 57321 | AP35: 96624 | AS35: 437283 | AT35: 244926 | AU35: 682209 | AY35: 61281 | AZ35: 61281 | BC35: 524106 | BD35: 181962 | BE35: 706068 | BF35: =BK35+BP35+BU35+BZ35+CE35 -> 0 | BG35: =BL35+BQ35+BV35+CA35+CF35 -> 0 | BH35: =BM35+BR35+BW35+CB35+CG35 -> 224334 | BI35: =BN35+BS35+BX35+CC35+CH35 -> 308385 | BJ35: =BO35+BT35+BY35+CD35+CI35 -> 532719 | BM35: 46332 | BN35: 62766 | BO35: 109098 | BR35: 94743 | BS35: 84645 | BT35: 179388 | BW35: 18117 | BX35: 119196 | BY35: 137313 | CB35: 53361 | CC35: 41778 | CD35: 95139 | CG35: 11781 | CI35: 11781
A36: DISNEY 汇总 | C36: =H36+BF36 -> 8647080 | D36: =I36+BG36 -> 9038499 | E36: =J36+BH36 -> 12395122 | F36: =K36+BI36 -> 12857796 | G36: =L36+BJ36 -> 42938497 | H36: =M36+R36+W36+AB36+AG36+AL36+AQ36+AV36+BA36 -> 6923725 | I36: =N36+S36+X36+AC36+AH36+AM36+AR36+AW36+BB36 -> 7129970 | J36: =O36+T36+Y36+AD36+AI36+AN36+AS36+AX36+BC36 -> 10283201 | K36: =P36+U36+Z36+AE36+AJ36+AO36+AT36+AY36+BD36 -> 10920039 | L36: =Q36+V36+AA36+AF36+AK36+AP36+AU36+AZ36+BE36 -> 35256935 | M36: 1743467 | N36: 1581449 | O36: 1722184 | P36: 2635956 | Q36: 7683056 | R36: 1154077 | S36: 1191772 | T36: 1500099 | U36: 1497608 | V36: 5343556 | W36: 328536 | X36: 347004 | Y36: 736143 | Z36: 855407 | AA36: 2267090 | AB36: 607993 | AC36: 1073625 | AD36: 1017270 | AE36: 1232359 | AF36: 3931247 | AG36: 1631063 | AH36: 1458409 | AI36: 2545219 | AJ36: 2609788 | AK36: 8244479 | AL36: 144169 | AM36: 217914 | AN36: 190647 | AO36: 215668 | AP36: 768398 | AQ36: 625818 | AR36: 556495 | AS36: 1045205 | AT36: 777574 | AU36: 3005092 | AV36: 105972 | AW36: 89984 | AX36: 125419 | AY36: 158689 | AZ36: 480064 | BA36: 582630 | BB36: 613318 | BC36: 1401015 | BD36: 936990 | BE36: 3533953 | BF36: =BK36+BP36+BU36+BZ36+CE36 -> 1723355 | BG36: =BL36+BQ36+BV36+CA36+CF36 -> 1908529 | BH36: =BM36+BR36+BW36+CB36+CG36 -> 2111921 | BI36: =BN36+BS36+BX36+CC36+CH36 -> 1937757 | BJ36: =BO36+BT36+BY36+CD36+CI36 -> 7681562 | BK36: 78469 | BL36: 67179 | BM36: 133737 | BN36: 113795 | BO36: 393180 | BP36: 1148686 | BQ36: 1259419 | BR36: 1209019 | BS36: 922859 | BT36: 4539983 | BU36: 377746 | BV36: 449114 | BW36: 595656 | BX36: 731383 | BY36: 2153899 | BZ36: 85145 | CA36: 76131 | CB36: 140200 | CC36: 142457 | CD36: 443933 | CE36: 33309 | CF36: 56686 | CG36: 33309 | CH36: 27263 | CI36: 150567
A37: HACIPUPU | B37: 潮流玩具 | C37: =H37+BF37 -> 3952268 | D37: =I37+BG37 -> 4787469 | E37: =J37+BH37 -> 4716414 | F37: =K37+BI37 -> 3681482 | G37: =L37+BJ37 -> 17137633 | H37: =M37+R37+W37+AB37+AG37+AL37+AQ37+AV37+BA37 -> 3872293 | I37: =N37+S37+X37+AC37+AH37+AM37+AR37+AW37+BB37 -> 4705212 | J37: =O37+T37+Y37+AD37+AI37+AN37+AS37+AX37+BC37 -> 4511949 | K37: =P37+U37+Z37+AE37+AJ37+AO37+AT37+AY37+BD37 -> 3390158 | L37: =Q37+V37+AA37+AF37+AK37+AP37+AU37+AZ37+BE37 -> 16479612 | M37: 320516 | N37: 413104 | O37: 525888 | P37: 361698 | Q37: 1621206 | R37: 365193 | S37: 204734 | T37: 404988 | U37: 431020 | V37: 1405935 | W37: 61545 | X37: 450816 | Y37: 386999 | Z37: 457515 | AA37: 1356875 | AB37: 123277 | AC37: 540088 | AD37: 825717 | AE37: 636138 | AF37: 2125220 | AG37: 2491310 | AH37: 1799721 | AI37: 1083579 | AJ37: 619661 | AK37: 5994271 | AL37: 14378 | AM37: 121027 | AN37: 97418 | AO37: 68287 | AP37: 301110 | AQ37: 314926 | AR37: 827184 | AS37: 860251 | AT37: 519645 | AU37: 2522006 | AV37: 10789 | AW37: 12749 | AX37: 24853 | AY37: 13647 | AZ37: 62038 | BA37: 170359 | BB37: 335789 | BC37: 302256 | BD37: 282547 | BE37: 1090951 | BF37: =BK37+BP37+BU37+BZ37+CE37 -> 79975 | BG37: =BL37+BQ37+BV37+CA37+CF37 -> 82257 | BH37: =BM37+BR37+BW37+CB37+CG37 -> 204465 | BI37: =BN37+BS37+BX37+CC37+CH37 -> 291324 | BJ37: =BO37+BT37+BY37+CD37+CI37 -> 658021 | BK37: 6040 | BL37: 7439 | BM37: 44098 | BN37: 28544 | BO37: 86121 | BP37: 29265 | BQ37: 27716 | BR37: 29633 | BS37: 93583 | BT37: 180197 | BU37: 24311 | BV37: 28993 | BW37: 118305 | BX37: 153631 | BY37: 325240 | BZ37: 5904 | CA37: 8994 | CB37: 6110 | CC37: 3818 | CD37: 24826 | CE37: 14455 | CF37: 9115 | CG37: 6319 | CH37: 11748 | CI37: 41637
B38: 潮流周边 | C38: =H38+BF38 -> 2014912 | D38: =I38+BG38 -> 1573275 | E38: =J38+BH38 -> 935625 | F38: =K38+BI38 -> 493342 | G38: =L38+BJ38 -> 5017154 | H38: =M38+R38+W38+AB38+AG38+AL38+AQ38+AV38+BA38 -> 1994890 | I38: =N38+S38+X38+AC38+AH38+AM38+AR38+AW38+BB38 -> 1560263 | J38: =O38+T38+Y38+AD38+AI38+AN38+AS38+AX38+BC38 -> 858849 | K38: =P38+U38+Z38+AE38+AJ38+AO38+AT38+AY38+BD38 -> 433987 | L38: =Q38+V38+AA38+AF38+AK38+AP38+AU38+AZ38+BE38 -> 4847989 | M38: 152758 | N38: 154074 | O38: 84478 | P38: 56904 | Q38: 448214 | R38: 124923 | S38: 38063 | T38: 31903 | U38: 10819 | V38: 205708 | W38: 120413 | X38: 414783 | Y38: 299504 | Z38: 56598 | AA38: 891298 | AB38: 58589 | AC38: 209672 | AD38: 16545 | AE38: 50821 | AF38: 335627 | AG38: 1256103 | AH38: 516643 | AI38: 204167 | AJ38: 132217 | AK38: 2109130 | AL38: 89692 | AM38: 20444 | AN38: 21136 | AO38: 21036 | AP38: 152308 | AQ38: 186360 | AR38: 98803 | AS38: 113817 | AT38: 71963 | AU38: 470943 | AV38: 636 | AW38: 1168 | AX38: 4390 | AY38: 1583 | AZ38: 7777 | BA38: 5416 | BB38: 106613 | BC38: 82909 | BD38: 32046 | BE38: 226984 | BF38: =BK38+BP38+BU38+BZ38+CE38 -> 20022 | BG38: =BL38+BQ38+BV38+CA38+CF38 -> 13012 | BH38: =BM38+BR38+BW38+CB38+CG38 -> 76776 | BI38: =BN38+BS38+BX38+CC38+CH38 -> 59355 | BJ38: =BO38+BT38+BY38+CD38+CI38 -> 169165 | BK38: 171 | BL38: 198 | BM38: 5912 | BN38: 712 | BO38: 6993 | BP38: 4689 | BQ38: 4484 | BR38: 16611 | BS38: 24573 | BT38: 50357 | BU38: 9429 | BV38: 4887 | BW38: 53659 | BX38: 27946 | BY38: 95921 | BZ38: 1662 | CA38: 572 | CD38: 2234 | CE38: 4071 | CF38: 2871 | CG38: 594 | CH38: 6124 | CI38: 13660
B39: 毛绒玩具 | C39: =H39+BF39 -> 1636887 | D39: =I39+BG39 -> 1470666 | E39: =J39+BH39 -> 985803 | F39: =K39+BI39 -> 2014129 | G39: =L39+BJ39 -> 6107485 | H39: =M39+R39+W39+AB39+AG39+AL39+AQ39+AV39+BA39 -> 1427334 | I39: =N39+S39+X39+AC39+AH39+AM39+AR39+AW39+BB39 -> 1322178 | J39: =O39+T39+Y39+AD39+AI39+AN39+AS39+AX39+BC39 -> 885477 | K39: =P39+U39+Z39+AE39+AJ39+AO39+AT39+AY39+BD39 -> 1902694 | L39: =Q39+V39+AA39+AF39+AK39+AP39+AU39+AZ39+BE39 -> 5537683 | M39: 1242 | N39: 7452 | P39: 22632 | Q39: 31326 | W39: 252609 | X39: 156078 | Y39: 165117 | Z39: 824964 | AA39: 1398768 | AB39: 2760 | AC39: 1725 | AD39: 146142 | AE39: 461265 | AF39: 611892 | AG39: 994980 | AH39: 870780 | AI39: 433251 | AJ39: 452019 | AK39: 2751030 | AL39: 5796 | AM39: 6624 | AN39: 21114 | AO39: 58581 | AP39: 92115 | AQ39: 24633 | AR39: 30498 | AS39: 89148 | AT39: 79093 | AU39: 223372 | AV39: 4968 | AW39: 7659 | AX39: 1518 | AZ39: 14145 | BA39: 140346 | BB39: 241362 | BC39: 29187 | BD39: 4140 | BE39: 415035 | BF39: =BK39+BP39+BU39+BZ39+CE39 -> 209553 | BG39: =BL39+BQ39+BV39+CA39+CF39 -> 148488 | BH39: =BM39+BR39+BW39+CB39+CG39 -> 100326 | BI39: =BN39+BS39+BX39+CC39+CH39 -> 111435 | BJ39: =BO39+BT39+BY39+CD39+CI39 -> 569802 | BL39: 8211 | BM39: 8901 | BN39: 11592 | BO39: 28704 | BP39: 34707 | BQ39: 34086 | BR39: 26220 | BS39: 23391 | BT39: 118404 | BU39: 122337 | BV39: 67068 | BW39: 37122 | BX39: 37950 | BY39: 264477 | BZ39: 31395 | CA39: 18492 | CB39: 1725 | CC39: 19665 | CD39: 71277 | CE39: 21114 | CF39: 20631 | CG39: 26358 | CH39: 18837 | CI39: 86940
